Traceback (most recent call last):
  File "/home/leobap/.local/lib/python3.8/site-packages/jupyter_cache/executors/utils.py", line 51, in single_nb_execution
    executenb(
  File "/home/leobap/.local/lib/python3.8/site-packages/nbclient/client.py", line 1204, in execute
    return NotebookClient(nb=nb, resources=resources, km=km, **kwargs).execute()
  File "/home/leobap/.local/lib/python3.8/site-packages/nbclient/util.py", line 84, in wrapped
    return just_run(coro(*args, **kwargs))
  File "/home/leobap/.local/lib/python3.8/site-packages/nbclient/util.py", line 62, in just_run
    return loop.run_until_complete(coro)
  File "/usr/lib/python3.8/asyncio/base_events.py", line 616, in run_until_complete
    return future.result()
  File "/home/leobap/.local/lib/python3.8/site-packages/nbclient/client.py", line 663, in async_execute
    await self.async_execute_cell(
  File "/home/leobap/.local/lib/python3.8/site-packages/nbclient/client.py", line 965, in async_execute_cell
    await self._check_raise_for_error(cell, cell_index, exec_reply)
  File "/home/leobap/.local/lib/python3.8/site-packages/nbclient/client.py", line 862, in _check_raise_for_error
    raise CellExecutionError.from_cell_and_msg(cell, exec_reply_content)
nbclient.exceptions.CellExecutionError: An error occurred while executing the following cell:
------------------
#b)

x=xI[:2]
p=pI[:2]

def henry(x):
    
    return K*x

popt, pcov = curve_fit(henry, x, p)


------------------

[0;31m---------------------------------------------------------------------------[0m
[0;31mValueError[0m                                Traceback (most recent call last)
Input [0;32mIn [8][0m, in [0;36m<cell line: 10>[0;34m()[0m
[1;32m      6[0m [38;5;28;01mdef[39;00m [38;5;21mhenry[39m(x):
[1;32m      8[0m     [38;5;28;01mreturn[39;00m K[38;5;241m*[39mx
[0;32m---> 10[0m popt, pcov [38;5;241m=[39m [43mcurve_fit[49m[43m([49m[43mhenry[49m[43m,[49m[43m [49m[43mx[49m[43m,[49m[43m [49m[43mp[49m[43m)[49m

File [0;32m/usr/lib/python3/dist-packages/scipy/optimize/minpack.py:683[0m, in [0;36mcurve_fit[0;34m(f, xdata, ydata, p0, sigma, absolute_sigma, check_finite, bounds, method, jac, **kwargs)[0m
[1;32m    681[0m     args, varargs, varkw, defaults [38;5;241m=[39m _getargspec(f)
[1;32m    682[0m     [38;5;28;01mif[39;00m [38;5;28mlen[39m(args) [38;5;241m<[39m [38;5;241m2[39m:
[0;32m--> 683[0m         [38;5;28;01mraise[39;00m [38;5;167;01mValueError[39;00m([38;5;124m"[39m[38;5;124mUnable to determine number of fit parameters.[39m[38;5;124m"[39m)
[1;32m    684[0m     n [38;5;241m=[39m [38;5;28mlen[39m(args) [38;5;241m-[39m [38;5;241m1[39m
[1;32m    685[0m [38;5;28;01melse[39;00m:

[0;31mValueError[0m: Unable to determine number of fit parameters.
ValueError: Unable to determine number of fit parameters.

